...F.....
======================================================================
FAIL: test_print_4 (__main__.TestPFD)
----------------------------------------------------------------------
Traceback (most recent call last):
  File "TestPFD.py", line 137, in test_print_4
    self.assert_(w.getvalue() == "900 1000 174 41 87 5 2")
AssertionError

----------------------------------------------------------------------
Ran 9 tests in 0.001s

FAILED (failures=1)
TestPFD.py
1
10
20
100
200
125
400
8
7
201
210
89
-1
-2
-100
500
900
1000
174
972699
998031
440
